class CustomError(Exception):
    pass


class B:
    def func1(self, arg1) -> None:
        """
        Do something

        :param arg1: Arg 1
        :return: None
        :rtype: None
        """
        a = 1
        b = 2
        raise ValueError('Hello world')

    def func2(self):
        raise Exception

    def func3(self, arg1):
        """Do something"""
        if arg1 > 2:
            raise TypeError

    def func4(self):
        """
        Do something.

        :raises: CurtomError: When something goes wrong
        """
        raise CustomError('CustomError')

    def func5(self):
        """
        Do something

        :return: Result
        :rtype: int
        :raises: TypeError: When something goes wrong
        """

        def func5_child1():
            raise ValueError

        return 1

    def func6(self, arg1):
        """
        Do something

        :param arg1: Arg1
        :return: Result
        :rtype: int
        :raises: TypeError: When something goes wrong
        """
        if arg1 is None:
            raise TypeError

        return arg1 + 2

    def func7(self, arg1):
        """
        Do something

        :param arg1: Arg1
        :return: Result
        :rtype: int
        :raises: TypeError: When something goes wrong
        """
        return 2

    def func8(self) -> None:
        """This is a function.

        :raises: FileNotFoundError: If the file does not exist.
        """
        try:
            open('nonexistent')
        except FileNotFoundError:
            raise

    def func9a(self, arg0) -> None:
        """
        There should be DOC502 for this outer method.

        :param arg0: Arg 0
        :raises: FileNotFoundError: If the file does not exist.
        """

        def inner9a(arg1) -> None:
            """
            There should be DOC501 for this inner method

            :param arg1: Arg 1
            """
            try:
                open('nonexistent')
            except FileNotFoundError:
                raise

        print(arg0)

    def func9b(self, arg0) -> None:
        """
        There should not be any violations in this outer method.

        :param arg0: Arg 0
        """

        def inner9a(arg1) -> None:
            """
            There should not be any violations in this inner method.

            :param arg1: Arg1
            :raises: FileNotFoundError: If the file does not exist.
            """
            try:
                open('nonexistent')
            except FileNotFoundError:
                raise

        print(arg0)

    def func11(self, arg0) -> None:
        """
        This docstring doesn't specify all the raised exceptions.

        :param arg0: Arg 0
        :raises TypeError: if arg0 is zero.
        """
        if arg0 == 0:
            raise TypeError
        raise ValueError

    def func12(self, arg0) -> None:
        """
        There should not be any violations in this method.

        :param arg0: Arg 0
        :raises TypeError: if arg0 is zero.
        :raises ValueError: otherwise.
        """
        if arg0 == 0:
            raise TypeError
        raise ValueError

    def func13(self) -> None:
        """
        Should raise an error due to duplicated raises.

        :raises ValueError: all the time.
        :raises ValueError: typo!
        """
        raise ValueError
